<?xml version="1.0" encoding="UTF-8"?>
<testng-results skipped="0" failed="1" ignored="0" total="3" passed="2">
  <reporter-output>
  </reporter-output>
  <suite name="autotest" duration-ms="991" started-at="2023-05-30T08:10:00Z" finished-at="2023-05-30T08:10:01Z">
    <groups>
    </groups>
    <test name="allTestsInAPackage" duration-ms="991" started-at="2023-05-30T08:10:00Z" finished-at="2023-05-30T08:10:01Z">
      <class name="org.example.AppTest">
        <test-method status="PASS" signature="getRequirementListTest001()[pri:0, instance:org.example.AppTest@7a5d012c]" name="getRequirementListTest001" duration-ms="910" started-at="2023-05-30T08:10:00Z" finished-at="2023-05-30T08:10:01Z">
          <reporter-output>
          </reporter-output>
        </test-method> <!-- getRequirementListTest001 -->
        <test-method status="PASS" signature="loginTest001()[pri:0, instance:org.example.AppTest@7a5d012c]" name="loginTest001" duration-ms="22" started-at="2023-05-30T08:10:01Z" description="用户名或密码错误" finished-at="2023-05-30T08:10:01Z">
          <reporter-output>
          </reporter-output>
        </test-method> <!-- loginTest001 -->
        <test-method status="FAIL" signature="loginTest002()[pri:0, instance:org.example.AppTest@7a5d012c]" name="loginTest002" duration-ms="20" started-at="2023-05-30T08:10:01Z" description="登录成功" finished-at="2023-05-30T08:10:01Z">
          <exception class="java.lang.AssertionError">
            <message>
              <![CDATA[expected [10] but found [0]]]>
            </message>
            <full-stacktrace>
              <![CDATA[java.lang.AssertionError: expected [10] but found [0]
at org.testng.Assert.fail(Assert.java:96)
at org.testng.Assert.failNotEquals(Assert.java:776)
at org.testng.Assert.assertEqualsImpl(Assert.java:137)
at org.testng.Assert.assertEquals(Assert.java:118)
at org.testng.Assert.assertEquals(Assert.java:442)
at org.example.AppTest.loginTest002(AppTest.java:43)
at sun.reflect.NativeMethodAccessorImpl.invoke0(Native Method)
at sun.reflect.NativeMethodAccessorImpl.invoke(NativeMethodAccessorImpl.java:62)
at sun.reflect.DelegatingMethodAccessorImpl.invoke(DelegatingMethodAccessorImpl.java:43)
at java.lang.reflect.Method.invoke(Method.java:498)
at org.testng.internal.MethodInvocationHelper.invokeMethod(MethodInvocationHelper.java:124)
at org.testng.internal.Invoker.invokeMethod(Invoker.java:583)
at org.testng.internal.Invoker.invokeTestMethod(Invoker.java:719)
at org.testng.internal.Invoker.invokeTestMethods(Invoker.java:989)
at org.testng.internal.TestMethodWorker.invokeTestMethods(TestMethodWorker.java:125)
at org.testng.internal.TestMethodWorker.run(TestMethodWorker.java:109)
at org.testng.TestRunner.privateRun(TestRunner.java:648)
at org.testng.TestRunner.run(TestRunner.java:505)
at org.testng.SuiteRunner.runTest(SuiteRunner.java:455)
at org.testng.SuiteRunner.runSequentially(SuiteRunner.java:450)
at org.testng.SuiteRunner.privateRun(SuiteRunner.java:415)
at org.testng.SuiteRunner.run(SuiteRunner.java:364)
at org.testng.SuiteRunnerWorker.runSuite(SuiteRunnerWorker.java:52)
at org.testng.SuiteRunnerWorker.run(SuiteRunnerWorker.java:84)
at org.testng.TestNG.runSuitesSequentially(TestNG.java:1208)
at org.testng.TestNG.runSuitesLocally(TestNG.java:1137)
at org.testng.TestNG.runSuites(TestNG.java:1049)
at org.testng.TestNG.run(TestNG.java:1017)
at com.intellij.rt.testng.IDEARemoteTestNG.run(IDEARemoteTestNG.java:66)
at com.intellij.rt.testng.RemoteTestNGStarter.main(RemoteTestNGStarter.java:109)
]]>
            </full-stacktrace>
          </exception> <!-- java.lang.AssertionError -->
          <reporter-output>
          </reporter-output>
        </test-method> <!-- loginTest002 -->
      </class> <!-- org.example.AppTest -->
    </test> <!-- allTestsInAPackage -->
  </suite> <!-- autotest -->
</testng-results>
